<?xml version="1.0" encoding="UTF-8"?>
<testsuites timestamp="2023-06-21T18:22:43.502" time="0.916" tests="18" skipped="0" failures="10" errors="5">
<testsuite name="test/testfiles/_retry_tests.jl" timestamp="2023-06-21T18:22:43.502" time="0.916" tests="18" skipped="0" failures="10" errors="5">
	<testcase name="Pass on second run" timestamp="2023-06-21T18:22:43.502" time="0.109" tests="1" skipped="0" failures="1" errors="0">
		<properties>
		<property name="dd_tags[perf.bytes]" value="2480386"></property>
		<property name="dd_tags[perf.allocs]" value="40352"></property>
		<property name="dd_tags[perf.gctime]" value="0.0"></property>
		<property name="dd_tags[perf.compile_time]" value="0.029507625"></property>
		<property name="dd_tags[perf.recompile_time]" value="0.0"></property>
		<property name="dd_tags[perf.eval_time]" value="0.003933915999999999"></property>
		</properties>
		<error message="Test failed at test/testfiles/_retry_tests.jl:17">Error in testset "Pass on second run" on worker 47971:
Test Failed at /Users/nickr/repos/ReTestItems.jl/test/testfiles/_retry_tests.jl:17
  Expression: x
Captured logs for test setup "StatefulSetup" (dependency of "Pass on second run") at test/testfiles/_retry_tests.jl:1 on worker 47971
These are the test setup logs.
No Captured Logs for test item "Pass on second run" at test/testfiles/_retry_tests.jl:12 on worker 47971
		</error>
	</testcase>
	<testcase name="Pass on second run" timestamp="2023-06-21T18:22:43.843" time="0.002" tests="1" skipped="0" failures="0" errors="0">
		<properties>
		<property name="dd_tags[perf.bytes]" value="79686"></property>
		<property name="dd_tags[perf.allocs]" value="1232"></property>
		<property name="dd_tags[perf.gctime]" value="0.0"></property>
		<property name="dd_tags[perf.compile_time]" value="8.3e-8"></property>
		<property name="dd_tags[perf.recompile_time]" value="0.0"></property>
		<property name="dd_tags[perf.eval_time]" value="0.002265376"></property>
		</properties>
	</testcase>
	<testcase name="Error, then Fail, then Pass" timestamp="2023-06-21T18:22:43.902" time="0.414" tests="1" skipped="0" failures="0" errors="1">
		<properties>
		<property name="dd_tags[perf.bytes]" value="72234978"></property>
		<property name="dd_tags[perf.allocs]" value="1344089"></property>
		<property name="dd_tags[perf.gctime]" value="0.00362875"></property>
		<property name="dd_tags[perf.compile_time]" value="0.353205166"></property>
		<property name="dd_tags[perf.recompile_time]" value="0.0"></property>
		<property name="dd_tags[perf.eval_time]" value="0.05755654199999999"></property>
		</properties>
		<error message="Error during test at test/testfiles/_retry_tests.jl:26">Error in testset "Error, then Fail, then Pass" on worker 47971:
Error During Test at /Users/nickr/repos/ReTestItems.jl/test/testfiles/_retry_tests.jl:26
  Test threw exception
  Expression: not_defined_err
  UndefVarError: not_defined_err not defined
  Stacktrace:
   [1] macro expansion
     @ /Applications/Julia-1.8.app/Contents/Resources/julia/share/julia/stdlib/v1.8/Test/src/Test.jl:464 [inlined]
   [2] top-level scope
     @ /repos/ReTestItems.jl/test/testfiles/_retry_tests.jl:26
Captured logs for test setup "StatefulSetup" (dependency of "Error, then Fail, then Pass") at test/testfiles/_retry_tests.jl:1 on worker 47971
These are the test setup logs.
Captured Logs for test item "Error, then Fail, then Pass" at test/testfiles/_retry_tests.jl:20 on worker 47971
These are the logs for run number: 1
		</error>
	</testcase>
	<testcase name="Error, then Fail, then Pass" timestamp="2023-06-21T18:22:44.386" time="0.008" tests="1" skipped="0" failures="1" errors="0">
		<properties>
		<property name="dd_tags[perf.bytes]" value="217427"></property>
		<property name="dd_tags[perf.allocs]" value="3710"></property>
		<property name="dd_tags[perf.gctime]" value="0.0"></property>
		<property name="dd_tags[perf.compile_time]" value="0.005068208"></property>
		<property name="dd_tags[perf.recompile_time]" value="0.0"></property>
		<property name="dd_tags[perf.eval_time]" value="0.003348167"></property>
		</properties>
		<error message="Test failed at test/testfiles/_retry_tests.jl:28">Error in testset "Error, then Fail, then Pass" on worker 47971:
Test Failed at /Users/nickr/repos/ReTestItems.jl/test/testfiles/_retry_tests.jl:28
  Expression: 2 + 2 == 5
   Evaluated: 4 == 5
Captured logs for test setup "StatefulSetup" (dependency of "Error, then Fail, then Pass") at test/testfiles/_retry_tests.jl:1 on worker 47971
These are the test setup logs.
Captured Logs for test item "Error, then Fail, then Pass" at test/testfiles/_retry_tests.jl:20 on worker 47971
These are the logs for run number: 2
		</error>
	</testcase>
	<testcase name="Error, then Fail, then Pass" timestamp="2023-06-21T18:22:44.454" time="0.003" tests="1" skipped="0" failures="0" errors="0">
		<properties>
		<property name="dd_tags[perf.bytes]" value="104078"></property>
		<property name="dd_tags[perf.allocs]" value="1714"></property>
		<property name="dd_tags[perf.gctime]" value="0.0"></property>
		<property name="dd_tags[perf.compile_time]" value="2.09e-7"></property>
		<property name="dd_tags[perf.recompile_time]" value="0.0"></property>
		<property name="dd_tags[perf.eval_time]" value="0.0034324579999999998"></property>
		</properties>
	</testcase>
	<testcase name="Has retries=4 and always fails" timestamp="2023-06-21T18:22:44.508" time="0.002" tests="1" skipped="0" failures="1" errors="0">
		<properties>
		<property name="dd_tags[perf.bytes]" value="76870"></property>
		<property name="dd_tags[perf.allocs]" value="1176"></property>
		<property name="dd_tags[perf.gctime]" value="0.0"></property>
		<property name="dd_tags[perf.compile_time]" value="1.67e-7"></property>
		<property name="dd_tags[perf.recompile_time]" value="0.0"></property>
		<property name="dd_tags[perf.eval_time]" value="0.00205225"></property>
		</properties>
		<error message="Test failed at test/testfiles/_retry_tests.jl:37">Error in testset "Has retries=4 and always fails" on worker 47971:
Test Failed at /Users/nickr/repos/ReTestItems.jl/test/testfiles/_retry_tests.jl:37
  Expression: false
Captured logs for test setup "StatefulSetup" (dependency of "Has retries=4 and always fails") at test/testfiles/_retry_tests.jl:1 on worker 47971
These are the test setup logs.
No Captured Logs for test item "Has retries=4 and always fails" at test/testfiles/_retry_tests.jl:34 on worker 47971
		</error>
	</testcase>
	<testcase name="Has retries=4 and always fails" timestamp="2023-06-21T18:22:44.562" time="0.002" tests="1" skipped="0" failures="1" errors="0">
		<properties>
		<property name="dd_tags[perf.bytes]" value="76870"></property>
		<property name="dd_tags[perf.allocs]" value="1176"></property>
		<property name="dd_tags[perf.gctime]" value="0.0"></property>
		<property name="dd_tags[perf.compile_time]" value="8.3e-8"></property>
		<property name="dd_tags[perf.recompile_time]" value="0.0"></property>
		<property name="dd_tags[perf.eval_time]" value="0.002100625"></property>
		</properties>
		<error message="Test failed at test/testfiles/_retry_tests.jl:37">Error in testset "Has retries=4 and always fails" on worker 47971:
Test Failed at /Users/nickr/repos/ReTestItems.jl/test/testfiles/_retry_tests.jl:37
  Expression: false
Captured logs for test setup "StatefulSetup" (dependency of "Has retries=4 and always fails") at test/testfiles/_retry_tests.jl:1 on worker 47971
These are the test setup logs.
No Captured Logs for test item "Has retries=4 and always fails" at test/testfiles/_retry_tests.jl:34 on worker 47971
		</error>
	</testcase>
	<testcase name="Has retries=4 and always fails" timestamp="2023-06-21T18:22:44.618" time="0.002" tests="1" skipped="0" failures="1" errors="0">
		<properties>
		<property name="dd_tags[perf.bytes]" value="76870"></property>
		<property name="dd_tags[perf.allocs]" value="1176"></property>
		<property name="dd_tags[perf.gctime]" value="0.0"></property>
		<property name="dd_tags[perf.compile_time]" value="2.08e-7"></property>
		<property name="dd_tags[perf.recompile_time]" value="0.0"></property>
		<property name="dd_tags[perf.eval_time]" value="0.0021199170000000002"></property>
		</properties>
		<error message="Test failed at test/testfiles/_retry_tests.jl:37">Error in testset "Has retries=4 and always fails" on worker 47971:
Test Failed at /Users/nickr/repos/ReTestItems.jl/test/testfiles/_retry_tests.jl:37
  Expression: false
Captured logs for test setup "StatefulSetup" (dependency of "Has retries=4 and always fails") at test/testfiles/_retry_tests.jl:1 on worker 47971
These are the test setup logs.
No Captured Logs for test item "Has retries=4 and always fails" at test/testfiles/_retry_tests.jl:34 on worker 47971
		</error>
	</testcase>
	<testcase name="Has retries=4 and always fails" timestamp="2023-06-21T18:22:44.673" time="0.002" tests="1" skipped="0" failures="1" errors="0">
		<properties>
		<property name="dd_tags[perf.bytes]" value="76870"></property>
		<property name="dd_tags[perf.allocs]" value="1176"></property>
		<property name="dd_tags[perf.gctime]" value="0.0"></property>
		<property name="dd_tags[perf.compile_time]" value="1.66e-7"></property>
		<property name="dd_tags[perf.recompile_time]" value="0.0"></property>
		<property name="dd_tags[perf.eval_time]" value="0.002009584"></property>
		</properties>
		<error message="Test failed at test/testfiles/_retry_tests.jl:37">Error in testset "Has retries=4 and always fails" on worker 47971:
Test Failed at /Users/nickr/repos/ReTestItems.jl/test/testfiles/_retry_tests.jl:37
  Expression: false
Captured logs for test setup "StatefulSetup" (dependency of "Has retries=4 and always fails") at test/testfiles/_retry_tests.jl:1 on worker 47971
These are the test setup logs.
No Captured Logs for test item "Has retries=4 and always fails" at test/testfiles/_retry_tests.jl:34 on worker 47971
		</error>
	</testcase>
	<testcase name="Has retries=4 and always fails" timestamp="2023-06-21T18:22:44.73" time="0.002" tests="1" skipped="0" failures="1" errors="0">
		<properties>
		<property name="dd_tags[perf.bytes]" value="76870"></property>
		<property name="dd_tags[perf.allocs]" value="1176"></property>
		<property name="dd_tags[perf.gctime]" value="0.0"></property>
		<property name="dd_tags[perf.compile_time]" value="8.4e-8"></property>
		<property name="dd_tags[perf.recompile_time]" value="0.0"></property>
		<property name="dd_tags[perf.eval_time]" value="0.002091374"></property>
		</properties>
		<error message="Test failed at test/testfiles/_retry_tests.jl:37">Error in testset "Has retries=4 and always fails" on worker 47971:
Test Failed at /Users/nickr/repos/ReTestItems.jl/test/testfiles/_retry_tests.jl:37
  Expression: false
Captured logs for test setup "StatefulSetup" (dependency of "Has retries=4 and always fails") at test/testfiles/_retry_tests.jl:1 on worker 47971
These are the test setup logs.
No Captured Logs for test item "Has retries=4 and always fails" at test/testfiles/_retry_tests.jl:34 on worker 47971
		</error>
	</testcase>
	<testcase name="Has retries=1 and always fails" timestamp="2023-06-21T18:22:44.782" time="0.002" tests="1" skipped="0" failures="1" errors="0">
		<properties>
		<property name="dd_tags[perf.bytes]" value="76870"></property>
		<property name="dd_tags[perf.allocs]" value="1176"></property>
		<property name="dd_tags[perf.gctime]" value="0.0"></property>
		<property name="dd_tags[perf.compile_time]" value="1.67e-7"></property>
		<property name="dd_tags[perf.recompile_time]" value="0.0"></property>
		<property name="dd_tags[perf.eval_time]" value="0.0020149169999999997"></property>
		</properties>
		<error message="Test failed at test/testfiles/_retry_tests.jl:43">Error in testset "Has retries=1 and always fails" on worker 47971:
Test Failed at /Users/nickr/repos/ReTestItems.jl/test/testfiles/_retry_tests.jl:43
  Expression: false
Captured logs for test setup "StatefulSetup" (dependency of "Has retries=1 and always fails") at test/testfiles/_retry_tests.jl:1 on worker 47971
These are the test setup logs.
No Captured Logs for test item "Has retries=1 and always fails" at test/testfiles/_retry_tests.jl:40 on worker 47971
		</error>
	</testcase>
	<testcase name="Has retries=1 and always fails" timestamp="2023-06-21T18:22:44.834" time="0.002" tests="1" skipped="0" failures="1" errors="0">
		<properties>
		<property name="dd_tags[perf.bytes]" value="76870"></property>
		<property name="dd_tags[perf.allocs]" value="1176"></property>
		<property name="dd_tags[perf.gctime]" value="0.0"></property>
		<property name="dd_tags[perf.compile_time]" value="4.1e-8"></property>
		<property name="dd_tags[perf.recompile_time]" value="0.0"></property>
		<property name="dd_tags[perf.eval_time]" value="0.002045293"></property>
		</properties>
		<error message="Test failed at test/testfiles/_retry_tests.jl:43">Error in testset "Has retries=1 and always fails" on worker 47971:
Test Failed at /Users/nickr/repos/ReTestItems.jl/test/testfiles/_retry_tests.jl:43
  Expression: false
Captured logs for test setup "StatefulSetup" (dependency of "Has retries=1 and always fails") at test/testfiles/_retry_tests.jl:1 on worker 47971
These are the test setup logs.
No Captured Logs for test item "Has retries=1 and always fails" at test/testfiles/_retry_tests.jl:40 on worker 47971
		</error>
	</testcase>
	<testcase name="Has retries=1 and always fails" timestamp="2023-06-21T18:22:44.888" time="0.002" tests="1" skipped="0" failures="1" errors="0">
		<properties>
		<property name="dd_tags[perf.bytes]" value="76870"></property>
		<property name="dd_tags[perf.allocs]" value="1176"></property>
		<property name="dd_tags[perf.gctime]" value="0.0"></property>
		<property name="dd_tags[perf.compile_time]" value="4.1e-8"></property>
		<property name="dd_tags[perf.recompile_time]" value="0.0"></property>
		<property name="dd_tags[perf.eval_time]" value="0.002284084"></property>
		</properties>
		<error message="Test failed at test/testfiles/_retry_tests.jl:43">Error in testset "Has retries=1 and always fails" on worker 47971:
Test Failed at /Users/nickr/repos/ReTestItems.jl/test/testfiles/_retry_tests.jl:43
  Expression: false
Captured logs for test setup "StatefulSetup" (dependency of "Has retries=1 and always fails") at test/testfiles/_retry_tests.jl:1 on worker 47971
These are the test setup logs.
No Captured Logs for test item "Has retries=1 and always fails" at test/testfiles/_retry_tests.jl:40 on worker 47971
		</error>
	</testcase>
	<testcase name="Timeout always" timestamp="2023-06-21T18:22:50.159" time="0.3" tests="1" skipped="0" failures="0" errors="1">
		<properties>
		<property name="dd_tags[perf.bytes]" value="0"></property>
		<property name="dd_tags[perf.allocs]" value="0"></property>
		<property name="dd_tags[perf.gctime]" value="0.0"></property>
		<property name="dd_tags[perf.compile_time]" value="0.0"></property>
		<property name="dd_tags[perf.recompile_time]" value="0.0"></property>
		<property name="dd_tags[perf.eval_time]" value="0.0"></property>
		</properties>
		<error message="Error during test at test/testfiles/_retry_tests.jl:54">Error in testset "Timeout always" on worker 48597:
Error During Test at /Users/nickr/repos/ReTestItems.jl/test/testfiles/_retry_tests.jl:54
  Got exception outside of a @test
  Timed out after 5s evaluating test item "Timeout always" (run=1)
Captured Logs for test item "Timeout always" at test/testfiles/_retry_tests.jl:54 on worker 48597

signal (15): Terminated: 15
in expression starting at /Users/nickr/repos/ReTestItems.jl/test/testfiles/_retry_tests.jl:60
__psynch_cvwait at /usr/lib/system/libsystem_kernel.dylib (unknown line)
unknown function (ip: 0x0)
kevent at /usr/lib/system/libsystem_kernel.dylib (unknown line)
unknown function (ip: 0x0)
Allocations: 5231242 (Pool: 5228911; Big: 2331); GC: 30
		</error>
	</testcase>
	<testcase name="Timeout always" timestamp="2023-06-21T18:22:56.246" time="0.0" tests="1" skipped="0" failures="0" errors="1">
		<properties>
		<property name="dd_tags[perf.bytes]" value="0"></property>
		<property name="dd_tags[perf.allocs]" value="0"></property>
		<property name="dd_tags[perf.gctime]" value="0.0"></property>
		<property name="dd_tags[perf.compile_time]" value="0.0"></property>
		<property name="dd_tags[perf.recompile_time]" value="0.0"></property>
		<property name="dd_tags[perf.eval_time]" value="0.0"></property>
		</properties>
		<error message="Error during test at test/testfiles/_retry_tests.jl:54">Error in testset "Timeout always" on worker 48597:
Error During Test at /Users/nickr/repos/ReTestItems.jl/test/testfiles/_retry_tests.jl:54
  Got exception outside of a @test
  Timed out after 5s evaluating test item "Timeout always" (run=2)
Captured Logs for test item "Timeout always" at test/testfiles/_retry_tests.jl:54 on worker 48597

signal (15): Terminated: 15
in expression starting at /Users/nickr/repos/ReTestItems.jl/test/testfiles/_retry_tests.jl:60
__psynch_cvwait at /usr/lib/system/libsystem_kernel.dylib (unknown line)
unknown function (ip: 0x0)
kevent at /usr/lib/system/libsystem_kernel.dylib (unknown line)
unknown function (ip: 0x0)
Allocations: 3068667 (Pool: 3067557; Big: 1110); GC: 3
		</error>
	</testcase>
	<testcase name="Timeout always" timestamp="2023-06-21T18:23:02.022" time="0.0" tests="1" skipped="0" failures="0" errors="1">
		<properties>
		<property name="dd_tags[perf.bytes]" value="0"></property>
		<property name="dd_tags[perf.allocs]" value="0"></property>
		<property name="dd_tags[perf.gctime]" value="0.0"></property>
		<property name="dd_tags[perf.compile_time]" value="0.0"></property>
		<property name="dd_tags[perf.recompile_time]" value="0.0"></property>
		<property name="dd_tags[perf.eval_time]" value="0.0"></property>
		</properties>
		<error message="Error during test at test/testfiles/_retry_tests.jl:54">Error in testset "Timeout always" on worker 48597:
Error During Test at /Users/nickr/repos/ReTestItems.jl/test/testfiles/_retry_tests.jl:54
  Got exception outside of a @test
  Timed out after 5s evaluating test item "Timeout always" (run=3)
Captured Logs for test item "Timeout always" at test/testfiles/_retry_tests.jl:54 on worker 48597

signal (15): Terminated: 15
in expression starting at /Users/nickr/repos/ReTestItems.jl/test/testfiles/_retry_tests.jl:60
__psynch_cvwait at /usr/lib/system/libsystem_kernel.dylib (unknown line)
unknown function (ip: 0x0)
kevent at /usr/lib/system/libsystem_kernel.dylib (unknown line)
unknown function (ip: 0x0)
Allocations: 3068817 (Pool: 3067707; Big: 1110); GC: 3
		</error>
	</testcase>
	<testcase name="Timeout first, pass after" timestamp="2023-06-21T18:23:07.785" time="0.0" tests="1" skipped="0" failures="0" errors="1">
		<properties>
		<property name="dd_tags[perf.bytes]" value="0"></property>
		<property name="dd_tags[perf.allocs]" value="0"></property>
		<property name="dd_tags[perf.gctime]" value="0.0"></property>
		<property name="dd_tags[perf.compile_time]" value="0.0"></property>
		<property name="dd_tags[perf.recompile_time]" value="0.0"></property>
		<property name="dd_tags[perf.eval_time]" value="0.0"></property>
		</properties>
		<error message="Error during test at test/testfiles/_retry_tests.jl:64">Error in testset "Timeout first, pass after" on worker 49020:
Error During Test at /Users/nickr/repos/ReTestItems.jl/test/testfiles/_retry_tests.jl:64
  Got exception outside of a @test
  Timed out after 5s evaluating test item "Timeout first, pass after" (run=1)
Captured Logs for test item "Timeout first, pass after" at test/testfiles/_retry_tests.jl:64 on worker 49020

signal (15): Terminated: 15
in expression starting at /Users/nickr/repos/ReTestItems.jl/test/testfiles/_retry_tests.jl:71
__psynch_cvwait at /usr/lib/system/libsystem_kernel.dylib (unknown line)
unknown function (ip: 0x0)
kevent at /usr/lib/system/libsystem_kernel.dylib (unknown line)
unknown function (ip: 0x0)
Allocations: 3061081 (Pool: 3059972; Big: 1109); GC: 3
		</error>
	</testcase>
	<testcase name="Timeout first, pass after" timestamp="2023-06-21T18:23:08.801" time="0.06" tests="1" skipped="0" failures="0" errors="0">
		<properties>
		<property name="dd_tags[perf.bytes]" value="8002663"></property>
		<property name="dd_tags[perf.allocs]" value="136514"></property>
		<property name="dd_tags[perf.gctime]" value="0.0"></property>
		<property name="dd_tags[perf.compile_time]" value="0.0521865"></property>
		<property name="dd_tags[perf.recompile_time]" value="0.0"></property>
		<property name="dd_tags[perf.eval_time]" value="0.0037945410000000054"></property>
		</properties>
	</testcase>
</testsuite>
</testsuites>